Workbook
Name ActNos: '[1]Actual Numbers'!$A$1:$M$53
Name asd: [2]WorkingPivot!$T:$Z
Name BasePoint: [3]WorkingPivots!$O$5
Name BrCodeBrName: [3]WorkingPivots!$AM$4:$AP$2503
Name DivisorBln: [3]WorkingPivots!$E$1
Name DivisorMn: [3]WorkingPivots!$D$1
Name DivisorThou: [4]WorkingPivots!$C$1
Name Down: '[5]Region wise'!$T$4
Name Equal: '[5]Region wise'!$S$4
Name gh: '[6]Snap-Shot'!$G$3
Name LastDay: [3]WorkingPivots!$M$5
Name LastMonth: [3]WorkingPivots!$N$5
Name LastWeekTrend: [3]WorkingPivots!$A$5:$H$24
Name LastWeekTrendInput: [3]Dashboard!$D$14
Name LastWeekTrendList: [3]WorkingPivots!$A$5:$A$24
Name LiabOD: '[1]Total Liab & OD'!$A$2:$Q$52
Name Link_AreaWise: [7]!Table_CategoriesMaker.accdb2[#All]
Name Link_BrWise: [7]!Table_CategoriesMaker.accdb[#Data]
Name LoV_Regions: [8]LoV!$B$1:$B$36
Name MIS_Date: '[5]Branch wise'!$B$3
Name MIS_Dt: '[9]Snap-Shot'!$G$3
Name MISDate: [4]Dashboard!$B$3
Name MTDC_BestWorst: [3]WorkingPivots!$X$4:$AC$33
Name MTDC_Input: [3]Dashboard!$D$35
Name NewBase: '[5]2015 Final Working'!$M$1:$P$1729
Name ODC_BestWorst: [3]WorkingPivots!$Q$4:$V$35
Name ODC_Dashboard: [3]Dashboard!$A$1
Name ODC_Input: [3]Dashboard!$D$23
Name Range_AreaWise: [5]WorkingPivot!$K:$Q
Name Range_FTM: [5]WorkingPivot!$B$8:$C$1638
Name Range_PWMTD: [10]br.Issuance!#REF!
Name Range_PWMTD: [10]br.Issuance!#REF!
Name Range_PWMTD: [10]br.Issuance!#REF!
Name Range_PWMTD: [10]br.Issuance!#REF!
Name Range_PWRED: [10]br.Issuance!#REF!
Name Range_PWRED: [10]br.Issuance!#REF!
Name Range_PWRED: [10]br.Issuance!#REF!
Name Range_PWRED: [10]br.Issuance!#REF!
Name Range_PWYTD: [10]br.Issuance!#REF!
Name Range_PWYTD: [10]br.Issuance!#REF!
Name Range_PWYTD: [10]br.Issuance!#REF!
Name Range_PWYTD: [10]br.Issuance!#REF!
Name Range_QTR: [5]WorkingPivot!$E$8:$F$1638
Name Range_Region: [5]WorkingPivot!$T:$Z
Name Range_YTD: [5]WorkingPivot!$H$8:$I$1638
Name RangeBMAllowance: [7]!Table_CategoriesMaker.accdb6[[#All],[Area Name]:[Eligibility]]
Name RegionInput: '[11]Main One Pager'!$D$4
Name RegionReportingLines: [12]RegionReporting!$A$1:$B$22
Name SPLM: [3]WorkingPivots!$A$39
Name SPLM_Text: [3]WorkingPivots!$A$40
Name SPLY: [3]WorkingPivots!$B$39
Name SPLY_Text: [3]WorkingPivots!$B$40
Name Static: [3]Dashboard!$X$5
Name Targets: [13]Target!$B$3:$CM$32
Name Term: [3]Dashboard!#REF!
Name Term: [3]Dashboard!#REF!
Name Term: [3]Dashboard!#REF!
Name Term: [3]Dashboard!#REF!
Name TodayStatus: [3]WorkingPivots!$L$5
Name TrendChecker: [3]WorkingPivots!$I$24

Sheet FP 2026
B3: Anum Vista
B4: Summary Sheet / Funds Position - 2026
F6: 46023 | J6: 46054 | O6: 46054 | S6: 46082
B8: Cash in Hand - Opening Balance | H8: 6442017 | L8: =+H38 -> 6352776 | Q8: =+H38 -> 6352776 | U8: =Q38 -> 6378113
B10: Inflow
C11: Maintenance | F11: =+'Recpt 2026'!D58 -> 262500 | J11: =+'Recpt 2026'!H58 -> 0 | O11: =+'Recpt 2026'!G58 -> 241500 | S11: =+'Recpt 2026'!J58 -> 171500
C12: Maintenance Shop A | F12: =+'Recpt 2026'!D61 -> 0 | J12: =+'Recpt 2026'!H61 -> 0 | O12: 0 | S12: 0
C13: Rent Community Hall | F13: =+'Recpt 2026'!D62 -> 0 | J13: =+'Recpt 2026'!H62 -> 0 | O13: 0 | S13: 0
C14: Advertisment | F14: =+'Recpt 2026'!D63+'Recpt 2026'!D64+'Recpt 2026'!D65 -> 500000 | J14: =+'Recpt 2026'!H63+'Recpt 2026'!H64+'Recpt 2026'!H65 -> 0 | O14: =+'Recpt 2026'!G63+'Recpt 2026'!G64+'Recpt 2026'!G65 -> 700000 | S14: =+'Recpt 2026'!J63+'Recpt 2026'!J64+'Recpt 2026'!J65 -> 1200000
C15: Advertisement Utility Bill Collection | F15: =+'Recpt 2026'!D67 -> 50000 | J15: =+'Recpt 2026'!H67 -> 0 | O15: 0 | S15: 0
C16: Scrap Sale | F16: =+'Recpt 2026'!D66 -> 27500 | J16: =+'Recpt 2026'!H66 -> 0 | O16: 0 | S16: 0
F17: =SUM(F11:F16) -> 840000 | J17: =SUM(J11:J16) -> 0 | O17: =SUM(O11:O16) -> 941500 | S17: =SUM(S11:S16) -> 1371500
B18: Outflow
C19: Water Tanker | F19: =+'Exp 2026'!D10 -> 0 | J19: =+'Exp 2026'!M10 -> 0 | O19: =+'Exp 2026'!F10 -> 15000 | S19: =+'Exp 2026'!H10 -> 0
C20: Salaries + Security Gurads | F20: =+'Exp 2026'!D19+'Exp 2026'!D22 -> 265000 | J20: =+'Exp 2026'!L19+'Exp 2026'!L22 -> 2 | O20: =+'Exp 2026'!F19+'Exp 2026'!F22 -> 225800 | S20: =+'Exp 2026'!H19+'Exp 2026'!H22 -> 276000
C21: Lift Work + Monthly Maintenance | F21: =+'Exp 2026'!D30 -> 21300 | J21: =+'Exp 2026'!L30 -> 0 | O21: =+'Exp 2026'!F30 -> 16500 | S21: =+'Exp 2026'!H30 -> 33000
C22: Petty Cash Expenses | F22: =+'Exp 2026'!D33 -> 15740 | J22: =+'Exp 2026'!L33 -> 0 | O22: =+'Exp 2026'!F33 -> 12560 | S22: =+'Exp 2026'!H33 -> 18170
C23: Utilities - Kelectric | F23: =+'Exp 2026'!D36 -> 226381 | J23: =+'Exp 2026'!L36 -> 0 | O23: =+'Exp 2026'!F36 -> 242468 | S23: =+'Exp 2026'!H36 -> 224818
C24: Electrical Work Expenses | F24: =+'Exp 2026'!D43 -> 34580 | J24: =+'Exp 2026'!L43 -> 0 | O24: =+'Exp 2026'!F43 -> 3640 | S24: =+'Exp 2026'!H43 -> 50110
C25: Generator & Diesel Exp | F25: =+'Exp 2026'!D49 -> 11500 | J25: =+'Exp 2026'!L49 -> 0 | O25: =+'Exp 2026'!F49 -> 53600 | S25: =+'Exp 2026'!H49 -> 92270
C26: Building Colour | F26: =+'Exp 2026'!D52 -> 0 | J26: =+'Exp 2026'!L52 -> 0 | O26: =+'Exp 2026'!F52 -> 169450 | S26: =+'Exp 2026'!H52 -> 0
C27: Building Maintenance - Others | F27: =+'Exp 2026'!D58 -> 18500 | J27: =+'Exp 2026'!L58 -> 0 | O27: =+'Exp 2026'!F58 -> 6600 | S27: =+'Exp 2026'!H58 -> 6970
C28: Play Area Expense | F28: =+'Exp 2026'!D62 -> 0 | J28: =+'Exp 2026'!L62 -> 0 | O28: =+'Exp 2026'!F62 -> 0 | S28: =+'Exp 2026'!H62 -> 15000
C29: Entertaiment Expense | F29: =+'Exp 2026'!D66 -> 0 | J29: =+'Exp 2026'!L66 -> 0 | O29: 0 | S29: =+'Exp 2026'!H66 -> 0
C30: Water - Machine and Plumbering Work | F30: =+'Exp 2026'!D78 -> 273740 | J30: =+'Exp 2026'!L78 -> 0 | O30: =+'Exp 2026'!F78 -> 83600 | S30: =+'Exp 2026'!H78 -> 5990
C31: Qurbani Expenses | F31: =+'Exp 2026'!D84 -> 0 | J31: =+'Exp 2026'!L84 -> 0 | O31: 0 | S31: =+'Exp 2026'!H84 -> 0
C32: Mosque/Ramzan Expenses | F32: =+'Exp 2026'!D91 -> 0 | J32: =+'Exp 2026'!L91 -> 0 | O32: =+'Exp 2026'!F91 -> 58445 | S32: =+'Exp 2026'!H91 -> 200230
C33: Gym Expense | F33: =+'Exp 2026'!D96 -> 0 | J33: =+'Exp 2026'!L96 -> 0 | O33: 0 | S33: =+'Exp 2026'!H96 -> 0
C34: Building Assets | F34: =+'Exp 2026'!D101 -> 50000 | J34: =+'Exp 2026'!L101 -> 0 | O34: =+'Exp 2026'!F101 -> 16000 | S34: =+'Exp 2026'!H101 -> 41000
C35: Camera, Intercom and Internet Expenses | F35: =+'Exp 2026'!D105 -> 12500 | J35: =+'Exp 2026'!L105 -> 0 | O35: =+'Exp 2026'!F105 -> 12500 | S35: =+'Exp 2026'!H105 -> 12500
F37: =SUM(F19:F36) -> 929241 | J37: =SUM(J19:J36) -> 2 | O37: =SUM(O19:O36) -> 916163 | S37: =SUM(S19:S36) -> 976058
B38: Cash in Hand - Closing Balance | H38: =H8+F17-F37 -> 6352776 | L38: =L8+J17-J37 -> 6352774 | Q38: =Q8+O17-O37 -> 6378113 | U38: =U8+S17-S37 -> 6773555
B40: Funds in Hand
C41: Danish | H41: =+'Funds Breakup'!C636 -> 2923241 | L41: =+'Funds Breakup'!G663 -> 0 | Q41: =+'Funds Breakup'!C663 -> 2923241 | U41: =+'Funds Breakup'!C690 -> 2923241
C42: Ali | H42: =+'Funds Breakup'!O636 -> 930000 | L42: =+'Funds Breakup'!S663 -> 0 | Q42: =+'Funds Breakup'!O663 -> 930000 | U42: =+'Funds Breakup'!O690 -> 930000
C43: Dilshad | H43: =+'Funds Breakup'!I636 -> 857518 | L43: =+'Funds Breakup'!M663 -> 0 | Q43: =+'Funds Breakup'!I663 -> 883823 | U43: =+'Funds Breakup'!I690 -> 1332583
C44: Asif | H44: =+'Funds Breakup'!L636 -> 1381000 | L44: =+'Funds Breakup'!P663 -> 0 | Q44: =+'Funds Breakup'!L663 -> 1381000 | U44: =+'Funds Breakup'!L690 -> 1381000
C45: Naveed | H45: =+'Funds Breakup'!F636 -> 261017 | L45: =+'Funds Breakup'!J663 -> 0 | Q45: =+'Funds Breakup'!F663 -> 260049 | U45: =+'Funds Breakup'!F690 -> 206731
H46: =SUM(H41:H45) -> 6352776 | L46: =SUM(L41:L45) -> 0 | Q46: =SUM(Q41:Q45) -> 6378113 | U46: =SUM(U41:U45) -> 6773555
H49: =H46-H38 -> 0 | L49: =L46-L38 -> -6352774 | Q49: =Q46-Q38 -> 0 | U49: =U46-U38 -> 0

Sheet Recpt 2026
B3: Anum Vista | Q3: Anum Vista
B4: Residents - Receipts - 2026 | Q4: Residents - Consolidated Oustanding Maintenance Position as of Jan 31, 2026
B5: Particulars | D5: 46023 | G5: 46054 | J5: 46082 | M5: 46113 | Q5: Appartment No. | R5: Name of Resident | S5: Monthly Maintenance | T5: Dues till Dec 31, 2025 | U5: Maintenance amunt till Mar 2026 | V5: Maintenance Recived during the Year 2026 | W5: Dues till Mar, 2026
B6: Residents Name | C6: Appartment No. | D6: Amount | E6: Receipt No. | F6: Date | G6: Amount | H6: Receipt No. | I6: Date | J6: Amount | K6: Receipt No. | L6: Date | M6: Amount | N6: Receipt No. | O6: Date
B8: Mr. Rehan | C8: 101 | D8: 28500 | E8: 229 | F8: 46028 | Q8: 101 | R8: Mr. Rehan | S8: =9500*12 -> 114000 | T8: 28500 | U8: =9500*3 -> 28500 | V8: =D8+G8+J8 -> 28500 | W8: =T8+U8-V8 -> 28500
B9: Mr. Faisal A. Khan | C9: 102 | D9: 14000 | E9: 239 | F9: 46030 | G9: 7000 | H9: 263 | I9: 46058 | J9: 7000 | K9: 287 | L9: 46085 | Q9: 102 | R9: Mr. Faisal A. Khan | S9: =7000*12 -> 84000 | T9: 28000 | U9: =7000*3 -> 21000 | V9: =D9+G9+J9 -> 28000 | W9: =T9+U9-V9 -> 21000
B10: Mrs. Rashid | C10: 103 | G10: 5000 | H10: 265 | I10: 46059 | Q10: 103 | R10: Mrs. Rashid | S10: =2500*12 -> 30000 | T10: 0 | U10: =2500*3 -> 7500 | V10: =D10+G10+J10 -> 5000 | W10: =T10+U10-V10 -> 2500
B11: Mr. Dilshad | C11: 104 | D11: 7000 | E11: 237 | F11: 46029 | G11: 7000 | H11: 254 | I11: 46055 | J11: 7000 | K11: 285 | L11: 46083 | Q11: 104 | R11: Mr. Dilshad | S11: =7000*12 -> 84000 | T11: 0 | U11: =7000*3 -> 21000 | V11: =D11+G11+J11 -> 21000 | W11: =T11+U11-V11 -> 0
B13: Mr. Ammar | C13: 201 | D13: 5500 | E13: 235 | F13: 46028 | G13: 5500 | H13: 255 | I13: 46055 | J13: 5500 | K13: 284 | L13: 46082 | M13: 5500 | N13: 308 | O13: 46114 | Q13: 201 | R13: Mr. Ammar | S13: =5500*12 -> 66000 | T13: 0 | U13: =5500*3 -> 16500 | V13: =D13+G13+J13 -> 16500 | W13: =T13+U13-V13 -> 0
B14: Mr. Faisal | C14: 202 | D14: 21000 | E14: 245 | F14: 46034 | Q14: 202 | R14: Mr. Faisal | S14: =7000*12 -> 84000 | T14: 14000 | U14: =7000+9000+9000 -> 25000 | V14: =D14+G14+J14 -> 21000 | W14: =T14+U14-V14 -> 18000
B15: Mr. Bakshish | C15: 203 | D15: 7000 | E15: 241 | F15: 46030 | Q15: 203 | R15: Mr. Bakshish | S15: =7000*12 -> 84000 | T15: 0 | U15: =7000*3 -> 21000 | V15: =D15+G15+J15 -> 7000 | W15: =T15+U15-V15 -> 14000
B16: Mr. Taimur | C16: 204 | D16: 7500 | E16: 251 | F16: 46052 | G16: 7500 | H16: 281 | I16: 46079 | J16: 7500 | K16: 302 | L16: 46101 | Q16: 204 | R16: Mr. Taimur | S16: =7500*12 -> 90000 | T16: 0 | U16: =7500*3 -> 22500 | V16: =D16+G16+J16 -> 22500 | W16: =T16+U16-V16 -> 0
B18: Mr. Zia | C18: 301 | D18: 5500 | E18: 233 | F18: 46027 | G18: 5500 | H18: 264 | I18: 46059 | J18: 5500 | K18: 294 | L18: 46088 | Q18: 301 | R18: Mr. Zia | S18: =5500*12 -> 66000 | T18: 0 | U18: =5500*3 -> 16500 | V18: =D18+G18+J18 -> 16500 | W18: =T18+U18-V18 -> 0
B19: Mr. Ashraf | C19: 302 | G19: 33000 | H19: 279 | I19: 46079 | Q19: 302 | R19: Mr. Ashraf | S19: =5500*12 -> 66000 | T19: 0 | U19: =5500*3 -> 16500 | V19: =D19+G19+J19 -> 33000 | W19: =T19+U19-V19 -> -16500
B20: Mr. Mubeen | C20: 303 | D20: 9000 | E20: 236 | F20: 46028 | G20: 9000 | H20: 269 | I20: 46062 | J20: 9000 | K20: 288 | L20: 46085 | Q20: 303 | R20: Mr. Mubeen | S20: =9000*12 -> 108000 | T20: 0 | U20: =9000*3 -> 27000 | V20: =D20+G20+J20 -> 27000 | W20: =T20+U20-V20 -> 0
B21: Mr. Farhan | C21: 304 | D21: 5500 | E21: 234 | F21: 46028 | G21: 5500 | H21: 261 | I21: 46058 | J21: 5500 | K21: 293 | L21: 46088 | Q21: 304 | R21: Mr. Farhan | S21: =5500*12 -> 66000 | T21: 0 | U21: =5500*3 -> 16500 | V21: =D21+G21+J21 -> 16500 | W21: =T21+U21-V21 -> 0
B23: Dr. Nazim | C23: 401 | D23: 9500 | E23: 230 | F23: 46026 | G23: 9500 | H23: 257 | I23: 46058 | J23: 9500 | K23: 289 | L23: 46085 | Q23: 401 | R23: Dr. Nazim | S23: =9500*12 -> 114000 | T23: 0 | U23: =9500*3 -> 28500 | V23: =D23+G23+J23 -> 28500 | W23: =T23+U23-V23 -> 0
B24: Mr. Junaid | C24: 402 | D24: 33000 | E24: 227 | F24: 46023 | Q24: 402 | R24: Mr. Junaid | S24: =5500*12 -> 66000 | T24: 0 | U24: =5500*3 -> 16500 | V24: =D24+G24+J24 -> 33000 | W24: =T24+U24-V24 -> -16500
B25: Mr. Asif Siddiqui | C25: 403 | Q25: 403 | R25: Mr. Asif Siddiqui | S25: =7000*12 -> 84000 | T25: 7000 | U25: =7000*3 -> 21000 | V25: =D25+G25+J25 -> 0 | W25: =T25+U25-V25 -> 28000
B26: Mr. Khalid Ashraf Lari | C26: 404 | Q26: 404 | R26: Mr. Khalid Ashraf Lari | S26: =7500*12 -> 90000 | T26: 22500 | U26: =5500*3 -> 16500 | V26: =D26+G26+J26 -> 0 | W26: =T26+U26-V26 -> 39000
B28: Mr. Tanveer Iqbal | C28: 501 | Q28: 501 | R28: Mr. Saad | S28: =7500*12 -> 90000 | T28: 7500 | U28: =7500*3 -> 22500 | V28: =D28+G28+J28 -> 0 | W28: =T28+U28-V28 -> 30000
B29: Mr. Naveed Ansari | C29: 502 | J29: 16500 | K29: 266 | L29: 46112 | Q29: 502 | R29: Mr. Naveed Ansari | S29: =5500*12 -> 66000 | T29: 16500 | U29: =5500*3 -> 16500 | V29: =D29+G29+J29 -> 16500 | W29: =T29+U29-V29 -> 16500
B30: Mr. Salman Khan | C30: 503 | Q30: 503 | R30: Mr. Salman Khan | S30: =7000*12 -> 84000 | T30: 0 | U30: =7000*3 -> 21000 | V30: =D30+G30+J30 -> 0 | W30: =T30+U30-V30 -> 21000
B31: Mr. Nafis | C31: 504 | D31: 5500 | E31: 228 | F31: 46027 | G31: 5500 | H31: 259 | I31: 46058 | J31: 5500 | K31: 290 | L31: 46087 | Q31: 504 | R31: Mr. Nafis | S31: =5500*12 -> 66000 | T31: 0 | U31: =5500*3 -> 16500 | V31: =D31+G31+J31 -> 16500 | W31: =T31+U31-V31 -> 0
B33: Mr. Sohail | C33: 601 | D33: 5500 | E33: 258 | F33: 46048 | G33: 5500 | H33: 280 | I33: 46080 | J33: 5500 | K33: 304 | L33: 46109 | Q33: 601 | R33: Mr. Sohail | S33: =5500*12 -> 66000 | T33: 0 | U33: =5500*3 -> 16500 | V33: =D33+G33+J33 -> 16500 | W33: =T33+U33-V33 -> 0
B34: Mr. Nasir | C34: 602 | D34: 5500 | E34: 243 | F34: 46037 | G34: 5500 | H34: 273 | I34: 46060 | J34: 5500 | K34: 298 | L34: 46092 | Q34: 602 | R34: Mr. Nasir | S34: =5500*12 -> 66000 | T34: 0 | U34: =5500*3 -> 16500 | V34: =D34+G34+J34 -> 16500 | W34: =T34+U34-V34 -> 0
B35: Mr. Shahid | C35: 603 | G35: 18000 | H35: 267 | I35: 46061 | Q35: 603 | R35: Mr. Shahid | S35: =9000*12 -> 108000 | T35: 27000 | U35: =9000*3 -> 27000 | V35: =D35+G35+J35 -> 18000 | W35: =T35+U35-V35 -> 36000
B36: Mr. Ashfaque Sb | C36: 604 | D36: 5500 | E36: 260 | F36: 46051 | G36: 5500 | H36: 292 | I36: 46081 | Q36: 604 | R36: Mr. Ashfaque Sb | S36: =5500*12 -> 66000 | T36: 0 | U36: =5500*3 -> 16500 | V36: =D36+G36+J36 -> 11000 | W36: =T36+U36-V36 -> 5500
B38: Mr. Owais | C38: 701 | D38: 5500 | E38: 244 | F38: 46033 | J38: 11000 | K38: 286 | L38: 46085 | Q38: 701 | R38: Mr. Owais | S38: =5500*12 -> 66000 | T38: 0 | U38: =5500*3 -> 16500 | V38: =D38+G38+J38 -> 16500 | W38: =T38+U38-V38 -> 0
B39: Mrs. Younus | C39: 702 | G39: 21500 | H39: 268 | I39: 46061 | J39: 5500 | K39: 303 | L39: 46097 | Q39: 702 | R39: Mrs. Younus | S39: =5500*12 -> 66000 | T39: 12000 | U39: =4000+5500+5500 -> 15000 | V39: =D39+G39+J39 -> 27000 | W39: =T39+U39-V39 -> 0
B40: Mr. Yousuf | C40: 703 | D40: 11000 | E40: 247 | F40: 46035 | G40: 11000 | H40: 271 | I40: 46065 | J40: 11000 | K40: 295 | L40: 46089 | Q40: 703 | R40: Mr. Yousuf | S40: =11000*12 -> 132000 | T40: 0 | U40: =11000*3 -> 33000 | V40: =D40+G40+J40 -> 33000 | W40: =T40+U40-V40 -> 0
B41: Mr. Taj | C41: 704 | D41: =7500+5500 -> 13000 | E41: 248/242 | F41: 12/13 Jan | G41: 5500 | H41: 275 | I41: 46069 | J41: 5500 | K41: 299 | L41: 46096 | Q41: 704 | R41: Mr. Taj | S41: =5500*12 -> 66000 | T41: 15000 | U41: =5500*3 -> 16500 | V41: =D41+G41+J41 -> 24000 | W41: =T41+U41-V41 -> 7500
B43: Mr. Kashif Patel | C43: 801 | G43: 11000 | H43: 274 | I43: 46068 | J43: 5500 | K43: 296 | L43: 46088 | Q43: 801 | R43: Mr. Kashif Patel | S43: =5500*12 -> 66000 | T43: 0 | U43: =5500*3 -> 16500 | V43: =D43+G43+J43 -> 16500 | W43: =T43+U43-V43 -> 0
B44: Mr. Munaf | C44: 802 | D44: 7500 | E44: 232 | F44: 46026 | G44: 7500 | H44: 270 | I44: 46065 | J44: 5500 | K44: 305 | L44: 46111 | Q44: 802 | R44: Mr. Munaf | S44: =7500*12 -> 90000 | T44: 0 | U44: =7500+7500+5500 -> 20500 | V44: =D44+G44+J44 -> 20500 | W44: =T44+U44-V44 -> 0
B45: Mr. Shamim | C45: 803 | D45: 7000 | E45: 231 | F45: 46026 | G45: 7000 | H45: 256 | I45: 46057 | J45: 7000 | K45: 301 | L45: 46098 | Q45: 803 | R45: Mr. Shamim | S45: =7000*12 -> 84000 | T45: 0 | U45: =7000*3 -> 21000 | V45: =D45+G45+J45 -> 21000 | W45: =T45+U45-V45 -> 0
B46: Mr. Aziz | C46: 804 | D46: 5500 | E46: 224 | F46: 46023 | G46: 5500 | H46: 252 | I46: 46054 | J46: 5500 | K46: 283 | L46: 46082 | M46: 5500 | N46: 307 | O46: 46113 | Q46: 804 | R46: Mr. Aziz | S46: =5500*12 -> 66000 | T46: 0 | U46: =5500*3 -> 16500 | V46: =D46+G46+J46 -> 16500 | W46: =T46+U46-V46 -> 0
B48: Mr. Fahad Qureshi | C48: 901 | Q48: 901 | R48: Mr. Fahad Qureshi | S48: =4000*12 -> 48000 | T48: 0 | U48: =4000*3 -> 12000 | V48: =D48+G48+J48 -> 0 | W48: =T48+U48-V48 -> 12000
B49: Mr. Arif 2 | C49: 902 | D49: 5500 | E49: 250 | F49: 46039 | G49: 5500 | H49: 278 | I49: 46079 | Q49: 902 | R49: Mr. Arif 2 | S49: =5500*12 -> 66000 | T49: 0 | U49: =5500*3 -> 16500 | V49: =D49+G49+J49 -> 11000 | W49: =T49+U49-V49 -> 5500
B50: Mr. Muhammad Arif | C50: 903 | D50: 7000 | E50: 249 | F50: 46039 | G50: 7000 | H50: 277 | I50: 46079 | Q50: 903 | R50: Mr. Muhammad Arif | S50: =7000*12 -> 84000 | T50: 0 | U50: =7000*3 -> 21000 | V50: =D50+G50+J50 -> 14000 | W50: =T50+U50-V50 -> 7000
B51: Mr. Hafeez | C51: 904 | D51: 5500 | E51: 246 | F51: 46034 | G51: 5500 | H51: 276 | I51: 46070 | J51: 5500 | K51: 300 | L51: 46096 | Q51: 904 | R51: Mr. Hafeez | S51: =5500*12 -> 66000 | T51: 0 | U51: =5500*3 -> 16500 | V51: =D51+G51+J51 -> 16500 | W51: =T51+U51-V51 -> 0
...

Sheet Exp 2026
B2: Anum Vista
B3: Expenses - Till Jul 2025
B4: Particulars | D4: 46023 | F4: 46054 | H4: 46054 | L4: Others - Petty Expenses
B5: Discription | C5: Name | L5: S. No. | M5: Particulors | N5: Date | O5: Amount
B6: Water Tanker | F6: 15000 | G6: 46068 | L6: 1 | M6: Garbage Collection | N6: 46051 | O6: 3000
L7: 2 | M7: Clearing Material - Albert | N7: 46035 | O7: 2800
L8: 3 | M8: Water - Aqua for Staff | N8: 46040 | O8: 5940
L9: 4 | M9: Air freshner | N9: 46035 | O9: 4000
D10: =SUM(D6:D9) -> 0 | F10: =SUM(F6:F9) -> 15000 | H10: =SUM(H6:H9) -> 0 | L10: 46023 | O10: =SUM(O6:O9) -> 15740
B11: Salaries and Wages | C11: Nadeem | D11: 40000 | E11: 46023 | F11: 40000 | G11: 46055 | H11: 50000 | I11: 46082
C12: Imam Sb | D12: 28000 | E12: 46023 | F12: 28000 | G12: 46055 | H12: 28000 | I12: 46082 | L12: S. No. | M12: Particulors | N12: Date | O12: Amount
C13: Adnan | D13: 26000 | E13: 46023 | F13: 15000 | G13: 46055 | H13: 31000 | I13: 46082 | L13: 1 | M13: Garbage Collection | N13: 46058 | O13: 3000
C14: Sajid | D14: 26000 | E14: 46023 | F14: 25000 | G14: 46055 | H14: 31000 | I14: 46082 | L14: 2 | M14: Clearing Material - Albert | N14: 3,19 Feb | O14: =7740+800 -> 8540
C15: Ali | D15: 13000 | E15: 46023 | F15: 0 | L15: 3 | M15: Water - Aqua for Staff | N15: Nil | O15: Nil
C16: Albert | D16: 37000 | E16: 46023 | F16: 37000 | G16: 46055 | H16: 42000 | I16: 46082 | L16: 4 | M16: Stationary | N16: 46056 | O16: 520
C17: Sunny/Matloob+Zara | D17: 30000 | E17: 46023 | F17: 9800 | G17: 46055 | H17: 14000 | I17: 46082 | L17: 5 | M17: Key Making | N17: 46067 | O17: 500
C18: Ahmed | F18: 6000 | G18: 46055 | H18: 10000 | I18: 46082 | L18: 46054 | O18: =SUM(O13:O17) -> 12560
D19: =SUM(D11:D18) -> 200000 | F19: =SUM(F11:F18) -> 160800 | H19: =SUM(H11:H18) -> 206000
B20: Murtaza Security | C20: Guard 1 | D20: 32500 | E20: 46031 | F20: 32500 | G20: 46055 | H20: 35000 | I20: 46086 | L20: S. No. | M20: Particulors | N20: Date | O20: Amount
C21: Guard 2 | D21: 32500 | E21: 46031 | F21: 32500 | G21: 46055 | H21: 35000 | I21: 46086 | L21: 1 | M21: Garbage Collection | N21: 46090 | O21: 3000
D22: =SUM(D20:D21) -> 65000 | F22: =SUM(F20:F21) -> 65000 | H22: =SUM(H20:H21) -> 70000 | L22: 2 | M22: Clearing Material - Albert | N22: 46092 | O22: 6930
B23: Lift Work + Monthly Maintenance | C23: Monthly Maintenance | D23: 12000 | E23: 46026 | F23: 12000 | G23: 46055 | H23: 12000 | I23: 46083 | L23: 3 | M23: Water - Aqua for Staff | N23: 46083 | O23: 3740
C24: Circuit Relay | D24: 3800 | E24: 46026 | L24: 4 | M24: Reception Chair repair | N24: 46098 | O24: 4500
C25: Lift Card repair | D25: 5500 | E25: 46048
C26: Button/Lift weight/Safety Switch | F26: 4500 | G26: 46055 | H26: 21000 | I26: 46097 | L26: 46082 | O26: =SUM(O21:O25) -> 18170
C27: Brake Shoes, Door repair, Oil
C28: Display Card / Invertor
C29: Mirror - Lift
D30: =SUM(D23:D29) -> 21300 | F30: =SUM(F23:F29) -> 16500 | H30: =SUM(H23:H29) -> 33000
B31: Others - Petty Expenses | D31: =+O10 -> 15740 | E31: Various | F31: =+O18 -> 12560 | G31: Various | H31: =+O26 -> 18170 | I31: Various
D33: =SUM(D31:D32) -> 15740 | F33: =SUM(F31:F32) -> 12560 | H33: =SUM(H31:H32) -> 18170
B34: Utilities | C34: KESC | D34: 226381 | E34: 46053 | F34: 242468 | G34: 46081 | H34: 224818 | I34: 46112
D36: =SUM(D34:D35) -> 226381 | F36: =SUM(F34:F35) -> 242468 | H36: =SUM(H34:H35) -> 224818
B37: Electrical work Expenses | C37: Other Electrical Material Purchases
C38: Lights - Purchases | D38: 33080 | E38: 46051 | F38: 3640 | G38: 46068 | H38: =3250+44860 -> 48110 | I38: 12,26 - Mar
C39: Labour | D39: 1500 | E39: 46035
C40: Gate Lock + Door Closer / Time Switch
C41: Fan Winding/Wire | H41: 2000 | I41: 46089
D43: =SUM(D37:D42) -> 34580 | F43: =SUM(F37:F42) -> 3640 | H43: =SUM(H37:H42) -> 50110
B44: Generator & Diesel Exp | C44: Maintenance | F44: 43600 | G44: 46079
...

Sheet Funds Breakup
B2: Danish | E2: Danish
B3: Particulars | C3: Amount | E3: Particulars | F3: Amount | G3: Remarks
B5: Opening Jan 01, 2024 | C5: 4082138
B7: Maintenance amount received by Danish | C7: =+'Recpt 2025'!AP58 -> 477000
B8: Maintenance Shop A | C8: =+'Recpt 2025'!AP61 -> 15000
B9: Community Hall Rent | C9: =+'Recpt 2025'!AP62 -> 0
B10: Advertisement - Asif (A) | C10: =+'Recpt 2025'!AP63 -> 1706250
B11: Advertisement - Raza (B) | C11: =+'Recpt 2025'!AP64 -> 0
B12: Advertisement - Khizer (C) | C12: =+'Recpt 2025'!AP65 -> 300000
B13: Salaries + Security Gurads | C13: =-Exp!AB23-Exp!AB26 -> -198500
B14: Water tanker | C14: =-Exp!AB14 -> -220000
B15: Petty Cash Expenses | C15: =-Exp!AB35 -> -14850
B16: Water - Machine and Plumbering Work | C16: =-Exp!AB85 -> -29960
B17: Generator & Diesel Exp | C17: =-Exp!AB57 -> -25000
B18: Lift Work + Monthly Maintenance | C18: =-Exp!AB34 -> -24500
B19: Electrical Work Expenses | C19: =-Exp!AB47 -> 0
B20: Kelectric - Jan 2024 | C20: =-Exp!AB40 -> -199495
B21: Gym Expenses | C21: =-Exp!AB102 -> 0
B22: Entertaiment Expense | C22: =-Exp!AB73 -> 0
B23: Building Colour Expenses | C23: =-Exp!AB62 -> 0
B24: Plants for building | C24: =-Exp!AB65 -> 0
B26: 45292 | C26: =SUM(C7:C25) -> 1785945
B28: Maintenance amount received by Danish | C28: =+'Recpt 2025'!AS58 -> 185500
B29: Maintenance Shop A | C29: =+'Recpt 2025'!AS61 -> 15000
B30: Community Hall Rent | C30: =+'Recpt 2025'!AS62 -> 0
B31: Advertisement - Asif (A) | C31: =+'Recpt 2025'!AS63 -> 0
B32: Advertisement - Raza (B) | C32: =+'Recpt 2025'!AS64 -> 0
B33: Advertisement - Khizer (C) | C33: =+'Recpt 2025'!AS65 -> 0
B34: Salaries + Security Gurads | C34: =-Exp!AD23-Exp!AD26 -> -200000
B35: Water tanker | C35: =-Exp!AD14 -> -210000
B36: Petty Cash Expenses | C36: =-Exp!AD37 -> -15100
B37: Water - Machine and Plumbering Work | C37: =-Exp!AD85 -> 0
B38: Generator & Diesel Exp | C38: =-Exp!AD57 -> -5000
B39: Lift Work + Monthly Maintenance | C39: =-Exp!AD34 -> -9500
B40: Electrical Work Expenses | C40: =-Exp!AD47 -> 0
B41: Kelectric - Feb 2024 | C41: =-Exp!AD40 -> -182471
B42: Gym Expenses | C42: =-Exp!AD102 -> 0
B43: Entertaiment Expense | C43: =-Exp!AD73 -> 0
B44: Building Colour Expenses | C44: =-Exp!AD62 -> 0
B45: Plants for building | C45: =-Exp!AD65 -> -44000
...

Sheet Advertisment
B3: Advertisement
B4: Adv Payment Duration | C4: Name | D4: Collection From Avertising | E4: Received Payments | F4: Payments Due | G4: Received Date
B5: 6 Month | C5: KHYZER | D5: 750000 | E5: Apr to sep-21 | F5: 44470
B6: 3 Month | C6: KHYZER | D6: 375000 | E6: Apr -May - Jun-21 | F6: 44378
B7: 3 Month | C7: Asif - Side A | D7: 825000 | E7: MAR-APR-MAY-2021 | F7: 44348
B8: 6 Month | C8: Raza - Side -B | D8: 400000 | E8: MAY to OCT-2021 | F8: 44499
B9: 3 Month | C9: Asif | D9: 990000 | E9: Jun-Jul-Aug-2021 | F9: 44440
D10: =SUM(D5:D9) -> 3340000
B11: 3 Months | C11: Asif - Side A | D11: =450000+457500 -> 907500 | E11: Sep-Oct-Nov-2021 | F11: 44440 | G11: 24 Sep, 15 Oct 2021
B12: 3 Months | C12: Asif - Side A | D12: 907500 | E12: Dec-Jan-Feb - 2022 | F12: 44531 | G12: 44563
B14: 3 Months | C14: Asif - Side A | D14: 812500 | E14: Mar - May 2022 | F14: 44621 | G14: 44635 | L14: =6500000 -> 6500000 | M14: =L14/4 -> 1625000 | N14: =M14/2 -> 812500 | Q14: =1625000*4 -> 6500000
B15: 3 Months | C15: Asif - Side A | D15: 812500 | E15: Mar - May 2022 | F15: 44621 | G15: 44651 | Q15: 800000
B16: 3 Months | C16: Asif - Side A | D16: =6500000/4 -> 1625000 | E16: Jun - Aug 2022 | F16: 44734 | G16: 44742 | Q16: 1200000
B17: 3 Months | C17: Asif - Side A | D17: =6500000/4 -> 1625000 | E17: Sep - Nov 2022 | F17: 44826 | G17: Rec in Oct, Nov & Dec 2022 | Q17: =SUM(Q14:Q16) -> 8500000
B18: 3 Months | C18: Asif - Side A | D18: =6500000/4 -> 1625000 | E18: Dec 2022 - Feb 2023 | F18: 44896 | G18: Rec in Jan, Feb and Mar 2023
B19: 3 Months | C19: Asif - Side A | D19: =+O19 -> 1706250 | E19: Mar 2023 - May 2023 | F19: 44986 | H19: Rec in Apr | L19: 6500000 | M19: =L19*5% -> 325000 | N19: =L19+M19 -> 6825000 | O19: =N19/4 -> 1706250
B20: 3 Months | C20: Asif - Side A | D20: =+O20 -> 1706250 | E20: Jun 2023 - Aug 2023 | F20: 45100 | H20: Rec in Jul | O20: 1706250
B21: 3 Months | C21: Asif - Side A | D21: =+O21 -> 1706250 | E21: Sep 2023 - Nov 2023 | F21: 45192 | H21: Rec in Oct | O21: 1706250
B22: 3 Months | C22: Asif - Side A | D22: =+O22 -> 1706250 | E22: Dec 2023 - Feb 2024 | F22: 45283 | H22: Rec in Jan 24 | O22: 1706250
B23: 3 Months | C23: Asif - Side A | D23: =+O23 -> 1791562.5 | E23: Mar 2024 - May 2024 | F23: 45352 | H23: Rec in Apr 24 | L23: =+N19 -> 6825000 | M23: =L23*5% -> 341250 | N23: =L23+M23 -> 7166250 | O23: =N23/4 -> 1791562.5
B24: 3 Months | C24: Asif - Side A | D24: =+O24 -> 1791563 | E24: Jun 2024 - Aug 2024 | F24: 45444 | H24: Rec in Jul 24 | O24: 1791563
B25: 3 Months | C25: Asif - Side A | D25: =+O25 -> 1791563 | E25: Sep 2024 - Nov 2024 | F25: 45536 | H25: Rec in Oct 24 | O25: 1791563
B26: 3 Months | C26: Asif - Side A | D26: =+O26 -> 1791563 | E26: Dec 2024 - Feb 2025 | F26: 45627 | H26: Rec in Jan 25 | O26: 1791563
B27: 3 Months | C27: Asif - Side A | D27: =+O27 -> 1881140.6 | E27: Mar 2025 - May 2025 | F27: 45717 | H27: Rec in May 25 | L27: =+N23 -> 7166250 | M27: =L27*5% -> 358312.5 | N27: =L27+M27 -> 7524562.5 | O27: =N27/4 -> 1881140.6 | AF27: Asif - Advertisement Payment
C28: Pending Mar - May | D28: =D26-D27 -> -89577.625 | E28: Mar 2025 - May 2025 | F28: 45717 | G28: Balance | O28: =+O27 -> 1881140.6
B29: 3 Months | C29: Asif - Side A | D29: =+O28 -> 1881140.6 | E29: Jun 2025 - Aug 2025 | F29: 45809 | H29: Rec in Aug 25, 1,100,000 Rec by Danish, 781,000 Rec by Asif | J29: =1881141 -> 1881141 | O29: =+O28 -> 1881140.6 | AF29: Jun to Aug 2025 | AH29: =D29 -> 1881140.6
B30: 3 Months | C30: Asif - Side A | D30: =600000+500000+600000+270000 -> 1970000 | E30: Sep 2025 - Nov 2025 | F30: 45901 | H30: 600k received By Asif, 500K 21/10/25, 600K 20/11/25, 270K 01/12/25 Remaining Rec by Dilshad | J30: 1700000 | O30: =+O29 -> 1881140.6
C31: Difference | D31: =D29-D30 -> -88859.375 | J31: =J29-J30 -> 181141 | L31: =+N27 -> 7524562.5 | M31: =L31*5% -> 376228.12 | N31: =L31+M31 -> 7900790.6 | O31: =N31/4 -> 1975197.7
C32: Received Pending Mar - May | D32: =-D28 -> 89577.625 | E32: =D31+D32 -> 718.25 | J32: =J31+D32 -> 270718.62 | R32: 500000 | S32: Rec. Dilshad | T32: 46010 | AF32: Paid to Danish Bhai | AH32: 1100000
B33: 3 Months | C33: Asif - Side A | D33: =500000+500000+500000 -> 1500000 | E33: Dec 2025 - Feb 2026 | F33: 45992 | H33: Received by Dilshad 500k 19/12/2025, 500k 20/01/2026, 500k 17/02/2026
D34: =D27-D33 -> 381140.62 | E34: Dec 2025 - Feb 2026 | F34: Mar Adjust | G34: =D34+D35 -> 1000000 | H34: Received by Dilshad 500k 02/03/2026, 500k 16/03/2026 | J34: =1881141 -> 1881141
D35: =500000+500000-D34 -> 618859.38 | E35: Mar 2026 - May 2026 | F35: Mar
D36: 2000000
D37: =D36-D35 -> 1381140.6
J39: =89578 -> 89578
B40: 6 Months | C40: Raza - Side -B | D40: 400000 | E40: Nov 2021 to Apr 2022 | F40: 44521 | G40: Rec Nov 02, 2021 | J40: =J34+J39 -> 1970719 | AF40: Remaining to be transferred to Muhammad Asif | AH40: =AH29-AH32 -> 781140.62
B41: 6 Months | C41: Raza - Side -B | D41: 400000 | E41: May 2022 to Oct 2022 | F41: 44682 | G41: Rec in May 2022
B42: 6 Months | C42: Raza - Side -B | D42: 400000 | E42: Nov 2022 to Apr 2023 | F42: 44866 | G42: Rec in Jan 2023
B43: 6 Months | C43: Raza - Side -B | D43: 400000 | E43: May 2023 to Oct 2023 | F43: 45047 | H43: Rec in May
B44: 6 Months | C44: Raza - Side -B | D44: 400000 | E44: Nov 2023 to Apr 2024 | F44: 45231 | H44: Rec in Oct
...

Sheet Sheet2
B2: Maintenance | N2: SALARIES | P2: Paid in Cash
B3: Received in Cash | H3: 801 | I3: Adnan | J3: 110 | K3: 4000 | L3: Aug
H4: 1001 | I4: Danish | J4: 109 | K4: 5500 | L4: Aug
B5: 502 | C5: Naveed | D5: 108 | E5: 5500 | F5: Aug | N5: Nadeem | O5: HO To Nadeem | P5: 35000
B6: 103 | C6: Mrs. Rashid | D6: 111 | E6: 2500 | F6: Aug | H6: 100000 | I6: Transfer to Danish Oct 04, 2025 | N6: Ali | O6: HO To Nadeem | P6: =22000-11000 -> 11000
N7: Adnan | O7: HO To Nadeem | P7: 23000
B8: 603 | C8: Shahid | D8: 101 | E8: 65000 | F8: Jan to Aug | G8: 72000 | N8: Albert | O8: HO To Nadeem | P8: 37000 | Q8: 20000 | R8: Advance paid to Dilshad
B9: 102 | C9: Faisal | D9: 114 | E9: 42000 | F9: Mar to Aug | H9: Trf to FBL account from Cash on Dec 25, 2025 = Total 60k from Shehroz | N9: Abrar | O9: HO To Nadeem | P9: 23000
B10: 302 | C10: Ashraf | D10: 115 | E10: 33000 | F10: Jul to Dec | H10: Trf to FBL account from Cash on Dec 25, 2025 = Total 49.5k from HBL | N10: Imam Sb | P10: 25000 | Q10: Transferred through FBL account
B11: 702 | C11: Mrs. Younus | D11: 131 | E11: 5500 | F11: Sep
B12: 1004 | C12: Ali | D12: 132 | E12: 5500 | F12: Sep | N12: Zaheer - Electrician | P12: 15000 | Q12: Transfer
B13: 504 | C13: Nafis | D13: 133 | E13: 5500 | F13: Sep
B14: 902 | C14: Taj | D14: 134 | E14: 5500 | F14: Sep
B15: 602 | C15: Nasir | D15: 135 | E15: 5500 | F15: Sep
B16: 601 | C16: Sohail | D16: 136 | E16: 5500 | F16: Sep | N16: Cash Receipt | P16: =E8+E11+E12+E13+E14+E15+E16+E17+E21+E22 -> 127500
B17: 603 | C17: Shahid | D17: 139 | E17: 9000 | F17: Sep | N17: Slaries Paid from Cash | P17: =SUM(P5:P9) -> 129000
B18: 502 | C18: Naveed | D18: 144 | E18: 5500 | F18: Sep
B19: 1001 | C19: Danish | D19: 146 | E19: 4000 | H19: Trf to FBL account from Cash on Dec 25, 2025 = Total 60k from Shehroz
B20: 103 | C20: Mrs. Rashid | D20: 147 | E20: 2500 | F20: Sep
B21: 701 | C21: Anis | D21: 150 | E21: 15000 | F21: Sep and Oct
B22: 504 | C22: Nafees | D22: 151 | E22: 5500 | F22: Oct
B23: 503 | C23: Salman | D23: 152 | E23: 14000 | F23: Sep and Oct | H23: Trf to FBL account from Cash on Dec 25, 2025 = Total 60k from Shehroz
B24: 901 | C24: Fahad | D24: 162 | E24: 16000 | F24: Sep to Dec | G24: 45942
B25: 1004 | C25: Ali | D25: 163 | E25: 5500 | F25: Oct'25 | G25: 45938
B26: 602 | C26: Nasir | D26: 164 | E26: 5500 | F26: Oct'25 | G26: 45941
B27: 902 | C27: Taj | D27: 165 | E27: 5500 | F27: Oct'25 | G27: 45942
B28: 601 | C28: Sohail | D28: 166 | E28: 5500 | F28: Oct'25 | G28: 45948
B29: 501 | C29: Tanveer | D29: 169 | E29: 16500 | F29: Feb+Mar+Apr | G29: 45956 | H29: Trf to FBL account from Cash on Dec 25, 2025 = Total 49.5k from HBL
B31: 1004 | C31: Ali | D31: 171 | E31: 4000 | F31: Com-Hall | G31: 45957
B32: 604 | C32: Ashfaq | D32: 172 | E32: 5500 | F32: Oct'25 | G32: 45961
B33: 201 | C33: Kashif | D33: 173 | E33: 5500 | F33: Nov'25 | G33: 45962 | H33: Deposited in Account by Asif against BC, Paid 10k cash to Noor | I33: 1000
B34: 504 | C34: Nafees | D34: 177 | E34: 5500 | F34: Nov'25 | G34: 45964 | H34: Deposited in Account by Asif against BC, Paid 10k cash to Noor
B35: 103 | C35: Mrs. Rashid | D35: 179 | E35: 2500 | F35: Oct'25 | G35: 45961
B36: 602 | C36: Nasir | D36: 192 | E36: 5500 | F36: Nov'25 | G36: 45977
B37: 902 | C37: Taj | D37: 193 | E37: 5500 | F37: Nov'25 | G37: 45977
B38: 601 | C38: Sohail | D38: 197 | E38: 5500 | F38: Nov'25 | G38: 45986
B39: 504 | C39: Nafees | D39: 214 | E39: 5500 | F39: Dec'25 | G39: 45995
B40: 602 | C40: Nasir | D40: 215 | E40: 5500 | F40: Dec'25 | G40: 46000
B41: 703 | C41: Junaid | D41: 216 | E41: 11000 | F41: Dec'25 | G41: 46009
B42: 103 | C42: Mrs. Rashid | D42: 222 | E42: 5000 | F42: Nov, Dec 2025 | G42: 46022 | I42: 325000 | M42: 325000 | O42: 460500 | Q42: 200000
...

Sheet Naveed
E3: Balance | J3: 7946
E5: Received | F5: Naveed - 502 | G5: Nov & Dec 2022 | H5: 11000
F6: Mohsin - 501 | G6: Oct & Nov 2022 | H6: 15000
F7: Rashid - 103 | G7: Nov & Dec 2022 | H7: 5000
H8: =SUM(H5:H7) -> 31000
E9: Expense | F9: Lights | G9: 44866 | H9: -21300
F10: Mats | G10: 44866 | H10: -8000
H11: =SUM(H8:H10) -> 1700 | J11: 1700
E13: Received | F13: Fahad - 901 | G13: Sep, Oct, Nov & Dec 2022 | H13: 16000
F14: Mohsin - 501 | G14: 44896 | H14: 7500
H15: =SUM(H13:H14) -> 23500
E16: Expense | F16: Cakes | G16: 44896 | H16: -23750
H17: =SUM(H15:H16) -> -250 | J17: -250
E19: Received | F19: Naveed - 502 | G19: Jan & Feb 2023 | H19: 11000
F20: Rashid - 103 | G20: Jan & Feb 2023 | H20: 5000
H21: =SUM(H19:H20) -> 16000
E22: Expense | F22: Lights - Bulb + Shade roll | G22: 44927 | H22: -16230
H23: =SUM(H21:H22) -> -230 | J23: -230
E25: Received | F25: Asif - 403 | G25: Maintenance | H25: 20600 | L25: Oct + Nov 14000, Mar & Apr 14000 + 4000 Community Hall - 11400 lights
F26: Shahid - 603 | G26: Dec 2022, Jan, Feb, Mar 2023 | H26: 34000 | L26: Dec 9000, Jan to Mar 8000 + including 1000 balance
F27: Naveed - 502 | G27: 44986 | H27: 5500
F28: Rashid - 103 | G28: 44986 | H28: 2500
H29: =SUM(H25:H28) -> 62600
E30: Expense | F30: Mosque Mic | H30: -3000
F31: Faraz for lights, cutain fittings | H31: -3000
F32: Carpet | H32: -11000
F33: Fabric for Staff | H33: -19300
F34: Mineral Water 19 litre | G34: 2 bottles | H34: =-290-290 -> -580
F35: Green Tea for Imam Sb. during Taraweah | H35: -180
F36: Material for building - Air Freshnors + Cells | H36: -3346
F37: Cold drink + Vaitor | H37: -2500
F38: Sweets - Khatam-e-Quran | H38: =-15401-3001 -> -18402
H39: =SUM(H29:H38) -> 1292 | J39: =+H39 -> 1292
F40: Apr & May
F41: Naveed - 502 | G41: Apr & May 2023 | H41: 11000
F42: Rashid - 103 | G42: Apr & May 2023 | H42: 5000
F43: Received from Danish | G43: 45112 | H43: 50000
F44: Colour Material | G44: 45112 | H44: -37150
F45: Wood and Carpentor Labour for duct | G45: 45112 | H45: -15000
F46: Received from Danish | G46: 45204 | H46: 50000
...

Sheet FP 2025
B3: Anum Vista
B4: Summary Sheet / Funds Position - 2025
F6: 45292 | J6: 45323 | N6: 45352 | R6: 45383 | V6: 45413 | Z6: 45444 | AD6: 45474 | AH6: 45505 | AL6: 45536 | AP6: 45566 | AT6: 45597 | AX6: 45627 | BB6: 45658 | BF6: 45689 | BJ6: 45717 | BN6: 45748 | BR6: 45778 | BV6: 45809 | BZ6: 45839 | CD6: 45870 | CH6: 45901 | CL6: 45931 | CP6: 45962 | CT6: 45992 | CX6: Total
B8: Cash in Hand - Opening Balance | H8: 4082138 | L8: =+H52 -> 5868083 | P8: =+L52 -> 5402512 | T8: =+P52 -> 4906871 | X8: =+T52 -> 6708131.5 | AB8: =+X52 -> 6335031.5 | AF8: =+AB52 -> 5916397.5 | AJ8: =+AF52 -> 7296569.5 | AN8: =+AJ52 -> 6644905.5 | AR8: =+AN52 -> 6393275.5 | AV8: =+AR52 -> 8088340.5 | AZ8: =+AV52 -> 7578686.5 | BD8: =+AZ52 -> 7140404.5 | BH8: =+BD52 -> 8934190.5 | BL8: =+BH52 -> 8376862.5 | BP8: =+BL52 -> 7269104.5 | BT8: =+BP52 -> 6903791.5 | BX8: =+BT52 -> 8155264.1 | CB8: =+BX52 -> 7555206.1 | CF8: =+CB52 -> 3819671.1 | CJ8: =+CF52 -> 6119099.1 | CN8: =+CJ52 -> 6605867.1 | CR8: =+CN52 -> 6121029.1 | CV8: =+CR52 -> 6154187.1
B10: Inflow
C11: Maintenance | F11: =+'Recpt 2025'!AP58 -> 477000 | J11: =+'Recpt 2025'!AS58 -> 185500 | N11: =+'Recpt 2025'!AV58 -> 213000 | R11: =+'Recpt 2025'!AY58 -> 376500 | V11: =+'Recpt 2025'!BB58 -> 161000 | Z11: =+'Recpt 2025'!BE58 -> 249500 | AD11: =+'Recpt 2025'!BH58 -> 173500 | AH11: =+'Recpt 2025'!BK58 -> 179000 | AL11: =+'Recpt 2025'!BN58 -> 290500 | AP11: =+'Recpt 2025'!BQ58 -> 254500 | AT11: =+'Recpt 2025'!BT58 -> 206500 | AX11: =+'Recpt 2025'!BW58 -> 406000 | BB11: =+'Recpt 2025'!CA58 -> 264500 | BF11: =+'Recpt 2025'!CD58 -> 161000 | BJ11: =+'Recpt 2025'!CG58 -> 257000 | BN11: =+'Recpt 2025'!CJ58 -> 120500 | BR11: =+'Recpt 2025'!CM58 -> 157500 | BV11: =+'Recpt 2025'!CP58 -> 215500 | BZ11: =+'Recpt 2025'!CS58 -> 370500 | CD11: =+'Recpt 2025'!CV58 -> 912000 | CH11: =+'Recpt 2025'!CY58 -> 300500 | CL11: =+'Recpt 2025'!DB58 -> 232500 | CP11: =+'Recpt 2025'!DE58 -> 200000 | CT11: =+'Recpt 2025'!DH58 -> 163001 | CX11: =+BB11+BF11+BJ11+BN11+BR11+BV11+BZ11+CD11 -> 2458500
C12: Maintenance Shop A | F12: =+'Recpt 2025'!AP61 -> 15000 | J12: =+'Recpt 2025'!AS61 -> 15000 | N12: 0 | R12: =+'Recpt 2025'!AY61 -> 0 | V12: 0 | Z12: =+'Recpt 2025'!BE61 -> 30000 | AD12: =+'Recpt 2025'!BH61 -> 0 | AH12: =+'Recpt 2025'!BL61 -> 0 | AL12: =+'Recpt 2025'!BN61 -> 0 | AP12: =+'Recpt 2025'!BQ61 -> 0 | AT12: =+'Recpt 2025'!BT61 -> 15000 | AX12: =+'Recpt 2025'!BW61 -> 0 | BB12: =+'Recpt 2025'!CA61 -> 0 | BF12: =+'Recpt 2025'!CD61 -> 0 | BJ12: =+'Recpt 2025'!CG61 -> 0 | BN12: =+'Recpt 2025'!CJ61 -> 0 | BR12: =+'Recpt 2025'!CM61 -> 0 | BV12: =+'Recpt 2025'!CP61 -> 0 | BZ12: =+'Recpt 2025'!CS61 -> 0 | CD12: =+'Recpt 2025'!CV61 -> 90000 | CH12: =+'Recpt 2025'!CY61 -> 0 | CL12: =+'Recpt 2025'!DB61 -> 0 | CP12: =+'Recpt 2025'!DE61 -> 7500 | CT12: =+'Recpt 2025'!DH61 -> 0 | CX12: =+BB12+BF12+BJ12+BN12+BR12+BV12+BZ12+CD12 -> 90000
C13: Rent Community Hall | F13: =+'Recpt 2025'!AP62 -> 0 | J13: =+'Recpt 2025'!AS62 -> 0 | N13: 0 | R13: =+'Recpt 2025'!AY62 -> 0 | V13: 0 | Z13: 0 | AD13: =+'Recpt 2025'!BH62 -> 0 | AH13: =+'Recpt 2025'!BL62 -> 0 | AL13: =+'Recpt 2025'!BN62 -> 0 | AP13: =+'Recpt 2025'!BQ62 -> 0 | AT13: =+'Recpt 2025'!BT62 -> 0 | AX13: =+'Recpt 2025'!BW62 -> 8000 | BB13: =+'Recpt 2025'!CA62 -> 0 | BF13: =+'Recpt 2025'!CD62 -> 0 | BJ13: =+'Recpt 2025'!CG62 -> 0 | BN13: =+'Recpt 2025'!CJ62 -> 0 | BR13: =+'Recpt 2025'!CM62 -> 8000 | BV13: =+'Recpt 2025'!CP62 -> 4000 | BZ13: =+'Recpt 2025'!CS62 -> 8000 | CD13: 0 | CH13: =+'Recpt 2025'!CY62 -> 0 | CL13: =+'Recpt 2025'!DB62 -> 4000 | CP13: =+'Recpt 2025'!DE62 -> 0 | CT13: =+'Recpt 2025'!DH62 -> 8000 | CX13: =+BB13+BF13+BJ13+BN13+BR13+BV13+BZ13+CD13 -> 20000
C14: Advertisment | F14: =+'Recpt 2025'!AP63+'Recpt 2025'!AP64+'Recpt 2025'!AP65 -> 2006250 | J14: =+'Recpt 2025'!AS63+'Recpt 2025'!AS64+'Recpt 2025'!AS65 -> 0 | N14: 0 | R14: =+'Recpt 2025'!AY63+'Recpt 2025'!AY64+'Recpt 2025'!AY65 -> 2091562.5 | V14: 0 | Z14: 0 | AD14: =+'Recpt 2025'!BH63+'Recpt 2025'!AY65 -> 2091563 | AH14: =+'Recpt 2025'!BL63+'Recpt 2025'!BC65 -> 0 | AL14: =+'Recpt 2025'!BN63+'Recpt 2025'!BN64+'Recpt 2025'!BN65 -> 0 | AP14: =+'Recpt 2025'!BQ63+'Recpt 2025'!BQ64+'Recpt 2025'!BQ65 -> 2091563 | AT14: =+'Recpt 2025'!BT63+'Recpt 2025'!BT64+'Recpt 2025'!BT65 -> 0 | AX14: =+'Recpt 2025'!BW63+'Recpt 2025'!BW64+'Recpt 2025'!BW65 -> 0 | BB14: =+'Recpt 2025'!CA63+'Recpt 2025'!CA64+'Recpt 2025'!CA65 -> 2091563 | BF14: =+'Recpt 2025'!CD63+'Recpt 2025'!CD64+'Recpt 2025'!CD65 -> 0 | BJ14: =+'Recpt 2025'!CG63+'Recpt 2025'!CG64+'Recpt 2025'!CG65 -> 100000 | BN14: =+'Recpt 2025'!CJ63+'Recpt 2025'!CJ64+'Recpt 2025'!CJ65 -> 300000 | BR14: =+'Recpt 2025'!CM63+'Recpt 2025'!CM64+'Recpt 2025'!CM65 -> 1791562.6 | BV14: =+'Recpt 2025'!CP63+'Recpt 2025'!CP64+'Recpt 2025'!CP65 -> 0 | BZ14: =+'Recpt 2025'!CS63+'Recpt 2025'!CS64+'Recpt 2025'!CS65 -> 0 | CD14: =+'Recpt 2025'!CV63+'Recpt 2025'!CV65 -> 2081000 | CH14: =+'Recpt 2025'!CY63+'Recpt 2025'!CY64+'Recpt 2025'!CY65 -> 1000000 | CL14: =+'Recpt 2025'!DB63 -> 500000 | CP14: =+'Recpt 2025'!DE63+'Recpt 2025'!DE64+'Recpt 2025'!DE65 -> 1020000 | CT14: =+'Recpt 2025'!DH63+'Recpt 2025'!DH65 -> 650000 | CX14: =+BB14+BF14+BJ14+BN14+BR14+BV14+BZ14+CD14 -> 6364125.6
C15: Scrap Sale | F15: 0 | J15: 0 | N15: 0 | R15: 0 | V15: 0 | Z15: 0 | AD15: 0 | AH15: 0 | AL15: 0 | AP15: 0 | AT15: 0 | AX15: 0 | BB15: =+'Recpt 2025'!CA66 -> 10000 | BF15: =+'Recpt 2025'!CD66 -> 60000 | BJ15: =+'Recpt 2025'!CG66 -> 0 | BN15: =+'Recpt 2025'!CJ66 -> 0 | BR15: 0 | BV15: =+'Recpt 2025'!CP66 -> 0 | BZ15: =+'Recpt 2025'!CS66 -> 0 | CD15: =+'Recpt 2025'!CV66 -> 0 | CH15: =+'Recpt 2025'!DB66 -> 0 | CT15: =+'Recpt 2025'!DH66 -> 50000 | CX15: =+BB15+BF15+BJ15+BN15+BR15+BV15+BZ15+CD15 -> 70000
F16: =SUM(F11:F15) -> 2498250 | J16: =SUM(J11:J15) -> 200500 | N16: =SUM(N11:N15) -> 213000 | R16: =SUM(R11:R15) -> 2468062.5 | V16: =SUM(V11:V15) -> 161000 | Z16: =SUM(Z11:Z15) -> 279500 | AD16: =SUM(AD11:AD15) -> 2265063 | AH16: =SUM(AH11:AH15) -> 179000 | AL16: =SUM(AL11:AL15) -> 290500 | AP16: =SUM(AP11:AP15) -> 2346063 | AT16: =SUM(AT11:AT15) -> 221500 | AX16: =SUM(AX11:AX15) -> 414000 | BB16: =SUM(BB11:BB15) -> 2366063 | BF16: =SUM(BF11:BF15) -> 221000 | BJ16: =SUM(BJ11:BJ15) -> 357000 | BN16: =SUM(BN11:BN15) -> 420500 | BR16: =SUM(BR11:BR15) -> 1957062.6 | BV16: =SUM(BV11:BV15) -> 219500 | BZ16: =SUM(BZ11:BZ15) -> 378500 | CD16: =SUM(CD11:CD15) -> 3083000 | CH16: =SUM(CH11:CH15) -> 1300500 | CL16: =SUM(CL11:CL15) -> 736500 | CP16: =SUM(CP11:CP15) -> 1227500 | CT16: =SUM(CT11:CT15) -> 871001 | CX16: =SUM(CX11:CX15) -> 9002625.6
B18: Outflow
C19: Water Tanker | F19: =+Exp!AB14 -> 220000 | J19: =+Exp!AD14 -> 210000 | N19: =+Exp!AF14 -> 110000 | R19: =+'Exp 2024'!J14 -> 11500 | V19: =+'Exp 2024'!L14 -> 0 | Z19: =+'Exp 2024'!P14 -> 0 | AD19: =+'Exp 2024'!P14 -> 0 | AH19: =+'Exp 2024'!R14 -> 0 | AL19: =+'Exp 2024'!T14 -> 0 | AP19: =+'Exp 2024'!V14 -> 0 | AT19: =+'Exp 2024'!X14 -> 26000 | AX19: =+'Exp 2024'!Z14 -> 52000 | BB19: =+'Exp 2025'!AC14 -> 0 | BF19: =+'Exp 2025'!AE14 -> 13000 | BJ19: =+'Exp 2025'!AG14 -> 13000 | BN19: =+'Exp 2025'!AI14 -> 0 | BR19: =+'Exp 2025'!AK7 -> 18000 | BV19: =+'Exp 2025'!AM14 -> 18000 | BZ19: =+'Exp 2025'!AO14 -> 30000 | CD19: =+'Exp 2025'!AQ14 -> 0 | CH19: =+'Exp 2025'!AS14 -> 60000 | CL19: =+'Exp 2025'!AU14 -> 132000 | CP19: =+'Exp 2025'!AW14 -> 129000 | CT19: =+'Exp 2025'!AY14 -> 15000 | CX19: =+BB19+BF19+BJ19+BN19+BR19+BV19+BZ19 -> 92000
C20: Utilities | F20: =+Exp!AB40 -> 199495 | J20: =+Exp!AD40 -> 182471 | N20: =+Exp!AF40 -> 182901 | R20: =+'Exp 2024'!J39 -> 253462 | V20: =+'Exp 2024'!L39 -> 271300 | Z20: =+'Exp 2024'!N39 -> 245427 | AD20: =+'Exp 2024'!P39 -> 283531 | AH20: =+'Exp 2024'!R39 -> 281334 | AL20: =+'Exp 2024'!T39 -> 236550 | AP20: =+'Exp 2024'!V39 -> 260098 | AT20: =+'Exp 2024'!X39 -> 267330 | AX20: =+'Exp 2024'!Z39 -> 255800 | BB20: =+'Exp 2025'!AC40 -> 204057 | BF20: =+'Exp 2025'!AE40 -> 192348 | BJ20: =+'Exp 2025'!AG40 -> 216757 | BN20: =+'Exp 2025'!AI40 -> 245053 | BR20: =+'Exp 2025'!AK40 -> 245240 | BV20: =+'Exp 2025'!AM40 -> 249608 | BZ20: =+'Exp 2025'!AO40 -> 235050 | CD20: =+'Exp 2025'!AQ40 -> 261172 | CH20: =+'Exp 2025'!AS40 -> 237312 | CL20: =+'Exp 2025'!AU40 -> 249928 | CP20: =+'Exp 2025'!AW40 -> 240498 | CT20: =+'Exp 2025'!AY40 -> 219111 | CX20: =+BB20+BF20+BJ20+BN20+BR20+BV20+BZ20 -> 1588113
C21: Salaries and Wages | F21: =+Exp!AB23 -> 148500 | J21: =+Exp!AD23 -> 150000 | N21: =+Exp!AF23 -> 159000 | R21: =+'Exp 2024'!J22 -> 161000 | V21: =+'Exp 2024'!L22 -> 160000 | Z21: =+'Exp 2024'!N22 -> 181000 | AD21: =+'Exp 2024'!P22 -> 161000 | AH21: =+'Exp 2024'!R22 -> 165000 | AL21: =+'Exp 2024'!T22 -> 168000 | AP21: =+'Exp 2024'!V22 -> 168000 | AT21: =+'Exp 2024'!X22 -> 152854 | AX21: =+'Exp 2024'!Z22 -> 152532 | BB21: =+'Exp 2025'!AC23 -> 166000 | BF21: =+'Exp 2025'!AE23 -> 166000 | BJ21: =+'Exp 2025'!AG23 -> 171600 | BN21: =+'Exp 2025'!AI23 -> 165000 | BR21: =+'Exp 2025'!AK23 -> 164000 | BV21: =+'Exp 2025'!AM23 -> 170100 | BZ21: =+'Exp 2025'!AO23 -> 160000 | CD21: =+'Exp 2025'!AQ23 -> 180000 | CH21: =+'Exp 2025'!AS23 -> 171500 | CL21: =+'Exp 2025'!AU23 -> 154000 | CP21: =+'Exp 2025'!AW23 -> 169200 | CT21: =+'Exp 2025'!AY23 -> 189600 | CX21: =+BB21+BF21+BJ21+BN21+BR21+BV21+BZ21 -> 1162700
C22: Security Guards | F22: =+Exp!AB26 -> 50000 | J22: =+Exp!AD26 -> 50000 | N22: =+Exp!AF26 -> 50000 | R22: =+'Exp 2024'!J25 -> 50000 | V22: =+'Exp 2024'!L25 -> 50000 | Z22: =+'Exp 2024'!N25 -> 50000 | AD22: =+'Exp 2024'!P25 -> 50000 | AH22: =+'Exp 2024'!R25 -> 50000 | AL22: =+'Exp 2024'!V25 -> 50000 | AP22: =+'Exp 2024'!V25 -> 50000 | AT22: =+'Exp 2024'!X25 -> 50000 | AX22: =+'Exp 2024'!Z25 -> 50000 | BB22: =+'Exp 2025'!AC26 -> 50000 | BF22: =+'Exp 2025'!AE26 -> 50000 | BJ22: =+'Exp 2025'!AG26 -> 50000 | BN22: =+'Exp 2025'!AI26 -> 50000 | BR22: =+'Exp 2025'!AK26 -> 50000 | BV22: =+'Exp 2025'!AM26 -> 65000 | BZ22: =+'Exp 2025'!AO26 -> 65000 | CD22: =+'Exp 2025'!AQ26 -> 65000 | CH22: =+'Exp 2025'!AS26 -> 65000 | CL22: =+'Exp 2025'!AU26 -> 65000 | CP22: =+'Exp 2025'!AW26 -> 65000 | CT22: =+'Exp 2025'!AY26 -> 65000 | CX22: =+BB22+BF22+BJ22+BN22+BR22+BV22+BZ22 -> 380000
C23: Lift Work + Monthly Maintenance | F23: =+Exp!AB34 -> 24500 | J23: =+Exp!AD34 -> 9500 | N23: =+Exp!AF34 -> 9500 | R23: =+'Exp 2024'!J33 -> 16000 | V23: =+'Exp 2024'!L33 -> 25100 | Z23: =+'Exp 2024'!N33 -> 5300 | AD23: =+'Exp 2024'!P33 -> 14300 | AH23: =+'Exp 2024'!R33 -> 12000 | AL23: =+'Exp 2024'!T33 -> 27550 | AP23: =+'Exp 2024'!V33 -> 17200 | AT23: =+'Exp 2024'!X33 -> 9500 | AX23: =+'Exp 2024'!Z33 -> 112300 | BB23: =+'Exp 2025'!AC34 -> 22000 | BF23: =+'Exp 2025'!AE34 -> 13200 | BJ23: =+'Exp 2025'!AG34 -> 10900 | BN23: =+'Exp 2025'!AI34 -> 98400 | BR23: =+'Exp 2025'!AK34 -> 11100 | BV23: =+'Exp 2025'!AM34 -> 12500 | BZ23: =+'Exp 2025'!AO34 -> 13900 | CD23: =+'Exp 2025'!AQ34 -> 19100 | CH23: =+'Exp 2025'!AS34 -> 18200 | CL23: =+'Exp 2025'!AU34 -> 16300 | CP23: =+'Exp 2025'!AW34 -> 10500 | CT23: =+'Exp 2025'!AY34 -> 9500 | CX23: =+BB23+BF23+BJ23+BN23+BR23+BV23+BZ23 -> 182000
C24: Others - Petty Expenses | F24: =+Exp!AB37 -> 14850 | J24: =+Exp!AD37 -> 15100 | N24: =+Exp!AF37 -> 17500 | R24: =+'Exp 2024'!J36 -> 19300 | V24: =+'Exp 2024'!L36 -> 10200 | Z24: =+'Exp 2024'!N36 -> 19257 | AD24: =+'Exp 2024'!P36 -> 24890 | AH24: =+'Exp 2024'!R36 -> 41230 | AL24: =+'Exp 2024'!T36 -> 24530 | AP24: =+'Exp 2024'!V36 -> 21500 | AT24: =+'Exp 2024'!X36 -> 15600 | AX24: =+'Exp 2024'!Z36 -> 20610 | BB24: =+'Exp 2025'!AC37 -> 29300 | BF24: =+'Exp 2025'!AE37 -> 35300 | BJ24: =+'Exp 2025'!AG37 -> 24690 | BN24: =+'Exp 2025'!AI37 -> 24000 | BR24: =+'Exp 2025'!AK37 -> 12750 | BV24: =+'Exp 2025'!AM37 -> 25100 | BZ24: =+'Exp 2025'!AO37 -> 30000 | CD24: =+'Exp 2025'!AQ37 -> 31500 | CH24: =+'Exp 2025'!AS37 -> 50840 | CL24: =+'Exp 2025'!AU37 -> 29800 | CP24: =+'Exp 2025'!AW37 -> 21150 | CT24: =+'Exp 2025'!AY37 -> 29910 | CX24: =+BB24+BF24+BJ24+BN24+BR24+BV24+BZ24 -> 181140
C25: Generator & Diesel Exp | F25: =+Exp!AB57 -> 25000 | J25: =+Exp!AD57 -> 5000 | N25: =+Exp!AF57 -> 10000 | R25: =+'Exp 2024'!J56 -> 0 | V25: =+'Exp 2024'!L56 -> 10000 | Z25: =+'Exp 2024'!N56 -> 45000 | AD25: =+'Exp 2024'!P56 -> 20000 | AH25: =+'Exp 2024'!R56 -> 30000 | AL25: =+'Exp 2024'!T56 -> 19500 | AP25: =+'Exp 2024'!V56 -> 25000 | AT25: =+'Exp 2024'!X56 -> 5000 | AX25: =+'Exp 2024'!Z56 -> 0 | BB25: =+'Exp 2025'!AC57 -> 58900 | BF25: =+'Exp 2025'!AE57 -> 5000 | BJ25: =+'Exp 2025'!AG57 -> 0 | BN25: =+'Exp 2025'!AI57 -> 5000 | BR25: =+'Exp 2025'!AK57 -> 15000 | BV25: =+'Exp 2025'!AM57 -> 10000 | BZ25: =+'Exp 2025'!AO57 -> 35000 | CD25: =+'Exp 2025'!AQ57 -> 60000 | CH25: =+'Exp 2025'!AS57 -> 30000 | CL25: =+'Exp 2025'!AU57 -> 25000 | CP25: =+'Exp 2025'!AW57 -> 20624 | CT25: =+'Exp 2025'!AY57 -> 5000 | CX25: =+BB25+BF25+BJ25+BN25+BR25+BV25+BZ25 -> 128900
C26: Entertainment Expense | F26: =+Exp!AB73 -> 0 | J26: =+Exp!AD73 -> 0 | N26: =+Exp!AF73 -> 17000 | R26: =+'Exp 2024'!J74 -> 0 | V26: 0 | Z26: 0 | AD26: =+'Exp 2024'!P74 -> 250000 | AH26: =+'Exp 2024'!R74 -> 0 | AL26: =+'Exp 2024'!T74 -> 0 | AP26: =+'Exp 2024'!V74 -> 0 | AT26: =+'Exp 2024'!X74 -> 123000 | AX26: 0 | BB26: =+'Exp 2025'!AC75 -> 0 | BF26: =+'Exp 2025'!AE75 -> 0 | BJ26: =+'Exp 2025'!AG75 -> 0 | BN26: =+'Exp 2025'!AI75 -> 0 | BR26: =+'Exp 2025'!AK75 -> 0 | BV26: =+'Exp 2025'!AM75 -> 250000 | BZ26: 0 | CD26: =+'Exp 2025'!AQ75 -> 1800 | CH26: =+'Exp 2025'!AS75 -> 0 | CL26: =+'Exp 2025'!AU75 -> 0 | CP26: 0 | CT26: 0 | CX26: =+BB26+BF26+BJ26+BN26+BR26+BV26+BZ26 -> 250000
C27: Building Expenses - Colour/Ramp Entrance filling | F27: =+Exp!AB62 -> 0 | J27: =+Exp!AD62 -> 0 | N27: =+Exp!AF62 -> 0 | R27: =+'Exp 2024'!J61 -> 0 | V27: 0 | Z27: 0 | AD27: 0 | AH27: =+'Exp 2024'!R60 -> 71000 | AL27: =+'Exp 2024'!T60 -> 6500 | AP27: 0 | AT27: =+'Exp 2024'!X60 -> 0 | AX27: =+'Exp 2024'!Z57+'Exp 2024'!Z58 -> 128540 | BB27: 0 | BF27: 0 | BJ27: 0 | BN27: =+'Exp 2025'!AI58 -> 27510 | BR27: 0 | BV27: 0 | BZ27: 0 | CD27: 0 | CH27: 0 | CL27: =+'Exp 2025'!AU62 -> 261190 | CP27: =+'Exp 2025'!AW62 -> 348160 | CT27: 0 | CX27: =+BB27+BF27+BJ27+BN27+BR27+BV27+BZ27 -> 27510
C28: Building Expenses - Reception Renovation work/Plants | F28: =+Exp!AB65 -> 0 | J28: =+Exp!AD65 -> 44000 | N28: =+Exp!AF63 -> 0 | R28: =+'Exp 2024'!J62 -> 0 | V28: 0 | Z28: 0 | AD28: 0 | AH28: =+'Exp 2024'!R62 -> 0 | AL28: =+'Exp 2024'!T57 -> 0 | AP28: =+'Exp 2024'!V62 -> 5300 | AT28: =+'Exp 2024'!X62 -> 5600 | AX28: =+'Exp 2024'!Z62 -> 46000 | BB28: 0 | BF28: =+'Exp 2025'!AE106 -> 25000 | BJ28: 0 | BN28: 0 | BR28: 0 | BV28: 0 | BZ28: =+'Exp 2025'!AO105 -> 2627500 | CD28: 0 | CH28: =+'Exp 2025'!AS67 -> 60000 | CL28: 0 | CP28: 0 | CT28: 0 | CX28: =+BB28+BF28+BJ28+BN28+BR28+BV28+BZ28 -> 2652500
C29: Building Expenses - Guard Room | N29: =+Exp!AF64 -> 15900 | R29: =+'Exp 2024'!J63 -> 0 | V29: 0 | Z29: 0 | AD29: 0 | AH29: 0 | AL29: 0 | AP29: 0 | AT29: 0 | AX29: 0 | BB29: 0 | BF29: 0 | BJ29: 0 | BN29: 0 | BR29: 0 | BV29: 0 | BZ29: =+'Exp 2025'!AO107 -> 238000 | CD29: 0 | CH29: 0 | CL29: 0 | CP29: 0 | CT29: 0 | CX29: =+BB29+BF29+BJ29+BN29+BR29+BV29+BZ29 -> 238000
C30: Building Expenses - Grill Work at 14th floor/Fire Refilling | Z30: =+'Exp 2024'!N65 -> 34500 | AD30: 0 | AH30: 0 | AL30: 0 | AP30: 0 | AT30: 0 | AX30: 0 | BB30: 0 | BF30: 0 | BJ30: 0 | BN30: 0 | BR30: 0 | BV30: 0 | BZ30: =+'Exp 2025'!AO108 -> 15000 | CD30: 0 | CH30: 0 | CL30: =+'Exp 2025'!AU113 -> 38300 | CP30: 0 | CT30: 0 | CX30: =+BB30+BF30+BJ30+BN30+BR30+BV30+BZ30 -> 15000
C31: Building Expenses - Vertical Acs for community hall | AH31: =+'Exp 2024'!R64 -> 32000 | AL31: 0 | AP31: 0 | AT31: 0 | AX31: 0 | BB31: 0 | BF31: 0 | BJ31: 0 | BN31: 0 | BR31: 0 | BV31: 0 | BZ31: =+'Exp 2025'!AO110 -> 422500 | CD31: 0 | CH31: 0 | CL31: 0 | CP31: 0 | CT31: 0 | CX31: =+BB31+BF31+BJ31+BN31+BR31+BV31+BZ31 -> 422500
C32: Electrical Appliances - Air Conditioners | BB32: 0 | BF32: =+'Exp 2025'!AE112 -> 220000 | BJ32: 0 | BN32: 0 | BR32: 0 | BV32: 0 | BZ32: 0 | CD32: 0 | CH32: 0 | CL32: 0 | CP32: 0 | CT32: 0 | CX32: =+BB32+BF32+BJ32+BN32+BR32+BV32+BZ32 -> 220000
C33: Power Factor + Installation Work | BB33: 0 | BF33: 0 | BJ33: =+'Exp 2025'!AG116 -> 350000 | BN33: =+'Exp 2025'!AI115 -> 20600 | BR33: =+'Exp 2025'!AK116 -> 150000 | BV33: 0 | BZ33: 0 | CD33: 0 | CH33: 0 | CL33: 0 | CP33: 0 | CT33: 0 | CX33: =+BB33+BF33+BJ33+BN33+BR33+BV33+BZ33 -> 520600
C34: Gym Expenses | F34: =+Exp!AB102 -> 0 | J34: =+Exp!AD102 -> 0 | N34: =+Exp!AF102 -> 0 | R34: =+'Exp 2024'!J103 -> 3500 | V34: 0 | Z34: =+'Exp 2024'!N103 -> 25000 | AD34: 0 | AH34: =+'Exp 2024'!R103 -> 21000 | AL34: =+'Exp 2024'!T101 -> 8000 | AP34: 0 | AT34: =+'Exp 2024'!X101 -> 0 | AX34: 0 | BB34: 0 | BF34: 0 | BJ34: =+'Exp 2025'!AG104 -> 420000 | BN34: =+'Exp 2025'!AI104 -> 0 | BR34: =+'Exp 2025'!AK104 -> 0 | BV34: 0 | BZ34: 0 | CD34: =+'Exp 2025'!AQ104 -> 17000 | CH34: =+'Exp 2025'!AS104 -> 5300 | CL34: =+'Exp 2025'!AU104 -> 0 | CP34: 0 | CT34: 0 | CX34: =+BB34+BF34+BJ34+BN34+BR34+BV34+BZ34 -> 420000
C35: Water - Machine and Plumbering Work | F35: =+Exp!AB85 -> 29960 | J35: =+Exp!AD85 -> 0 | N35: =+Exp!AF85 -> 37790 | R35: =+'Exp 2024'!J86 -> 22080 | V35: =+'Exp 2024'!L86 -> 0 | Z35: =+'Exp 2024'!N86 -> 17000 | AD35: =+'Exp 2024'!P86 -> 81170 | AH35: =+'Exp 2024'!R86 -> 17900 | AL35: =+'Exp 2024'!T86 -> 1500 | AP35: =+'Exp 2024'!V86 -> 23900 | AT35: =+'Exp 2024'!X86 -> 14570 | AX35: =+'Exp 2024'!Z86 -> 2500 | BB35: =+'Exp 2025'!AC87 -> 42020 | BF35: =+'Exp 2025'!AE87 -> 7080 | BJ35: =+'Exp 2025'!AG87 -> 32700 | BN35: =+'Exp 2025'!AI87 -> 123670 | BR35: =+'Exp 2025'!AK87 -> 2000 | BV35: =+'Exp 2025'!AM87 -> 0 | BZ35: =+'Exp 2025'!AO87 -> 131085 | CD35: =+'Exp 2025'!AQ87 -> 0 | CH35: =+'Exp 2025'!AS87 -> 49280 | CL35: =+'Exp 2025'!AU87 -> 74020 | CP35: =+'Exp 2025'!AW87 -> 57210 | CT35: =+'Exp 2025'!AY87 -> 11070 | CX35: =+BB35+BF35+BJ35+BN35+BR35+BV35+BZ35 -> 338555
C36: Qurbani Expenses | F36: =+Exp!AB91 -> 0 | J36: =+Exp!AD91 -> 0 | N36: =+Exp!AF91 -> 0 | R36: =+'Exp 2024'!J92 -> 0 | V36: 0 | Z36: =+'Exp 2024'!N92 -> 66050 | AD36: 0 | AH36: 0 | AL36: 0 | AP36: 0 | AT36: 0 | AX36: 0 | BB36: 0 | BF36: 0 | BJ36: 0 | BN36: =+'Exp 2025'!AI93 -> 0 | BR36: =+'Exp 2025'!AK93 -> 17500 | BV36: =+'Exp 2025'!AM93 -> 14000 | BZ36: 0 | CD36: 0 | CH36: 0 | CL36: =+'Exp 2025'!AU93 -> 9600 | CP36: 0 | CT36: 0 | CX36: =+BB36+BF36+BJ36+BN36+BR36+BV36+BZ36 -> 31500
C37: Mosque/Ramzan Expense | F37: =+Exp!AB98 -> 0 | J37: =+Exp!AD98 -> 0 | N37: =+Exp!AF98 -> 70150 | R37: =+'Exp 2024'!J99 -> 120460 | V37: 0 | Z37: 0 | AD37: 0 | AH37: 0 | AL37: 0 | AP37: 0 | AT37: 0 | AX37: 0 | BB37: 0 | BF37: =+'Exp 2025'!AE100 -> 51400 | BJ37: =+'Exp 2025'!AG100 -> 147561 | BN37: =+'Exp 2025'!AI100 -> 0 | BR37: 0 | BV37: 0 | BZ37: 0 | CD37: 0 | CH37: 0 | CL37: 0 | CP37: 0 | CT37: 0 | CX37: =+BB37+BF37+BJ37+BN37+BR37+BV37+BZ37 -> 198961
C38: Electrical work Expenses | F38: =+Exp!AB47 -> 0 | J38: =+Exp!AD47 -> 0 | N38: =+Exp!AF47 -> 21900 | R38: =+'Exp 2024'!J46 -> 1000 | V38: =+'Exp 2024'!L46 -> 7500 | Z38: =+'Exp 2024'!N46 -> 9600 | AD38: 0 | AH38: =+'Exp 2024'!R46 -> 9200 | AL38: =+'Exp 2024'!T46 -> 0 | AP38: =+'Exp 2024'!V46 -> 0 | AT38: =+'Exp 2024'!X46 -> 61700 | AX38: =+'Exp 2024'!Z46 -> 20000 | BB38: =+'Exp 2025'!AC47 -> 0 | BF38: =+'Exp 2025'!AE47 -> 0 | BJ38: =+'Exp 2025'!AG47 -> 27150 | BN38: =+'Exp 2025'!AI47 -> 6980 | BR38: =+'Exp 2025'!AK47 -> 20000 | BV38: =+'Exp 2025'!AM47 -> 5250 | BZ38: 0 | CD38: =+'Exp 2025'!AQ47 -> 9500 | CH38: =+'Exp 2025'!AS47 -> 48300 | CL38: =+'Exp 2025'!AU47 -> 101200 | CP38: =+'Exp 2025'!AW47 -> 24000 | CT38: =+'Exp 2025'!AY47 -> 38980 | CX38: =+BB38+BF38+BJ38+BN38+BR38+BV38+BZ38 -> 59380
C39: Play Area Expenses | F39: 0 | J39: 0 | N39: =+Exp!AF68 -> 7000 | R39: =+'Exp 2024'!J69 -> 8500 | V39: =+'Exp 2024'!N69 -> 0 | Z39: =+'Exp 2024'!X69 -> 0 | AD39: 0 | AH39: 0 | AL39: 0 | AP39: 0 | AT39: 0 | AX39: 0 | BB39: 0 | BF39: 0 | BJ39: =+'Exp 2025'!AG70 -> 400 | BN39: =+'Exp 2025'!AI70 -> 19600 | BR39: 0 | BV39: 0 | BZ39: =+'Exp 2025'!AO70 -> 31000 | CD39: 0 | CH39: 0 | CL39: 0 | CP39: 0 | CT39: 0 | CX39: =+BB39+BF39+BJ39+BN39+BR39+BV39+BZ39 -> 51000
C40: =+'Exp 2025'!B111 -> New Cameras Installation/Purchases | F40: 0 | J40: 0 | N40: 0 | R40: 0 | V40: 0 | Z40: 0 | AD40: 0 | AH40: 0 | AL40: 0 | AP40: 0 | AT40: 0 | AX40: 0 | BB40: 0 | BF40: 0 | BJ40: 0 | BN40: 0 | BR40: 0 | BV40: 0 | BZ40: =+'Exp 2025'!AO111 -> 80000 | CD40: =+'Exp 2025'!AQ112 -> 124000 | CH40: =+'Exp 2025'!AS111 -> 18000 | CL40: =+'Exp 2025'!AU112 -> 65000 | CP40: =+'Exp 2025'!AW112 -> 109000 | CT40: 0 | CX40: =+BB40+BF40+BJ40+BN40+BR40+BV40+BZ40 -> 80000
C41: Adjustment - Old Maintenance issue adjusted | CD41: =+'Recpt 2025'!CW81 -> 14500 | CH41: =+'Recpt 2025'!DA81 -> 0 | CP41: 0 | CT41: 0
C42: Registration Expense of AV Union | AH42: =+'Exp 2024'!R59 -> 100000 | AL42: 0 | AP42: =+'Exp 2024'!V59 -> 80000 | AT42: 0 | AX42: =+'Exp 2024'!Z59 -> 12000 | BB42: 0 | BF42: 0 | BJ42: 0 | BN42: 0 | BR42: 0 | BV42: 0 | CP42: 0 | CT42: 0 | CX42: =+BB42+BF42+BJ42+BN42+BR42+BV42+BZ42 -> 0
F43: =SUM(F19:F40) -> 712305 | J43: =SUM(J19:J40) -> 666071 | N43: =SUM(N19:N40) -> 708641 | R43: =SUM(R19:R40) -> 666802 | V43: =SUM(V19:V40) -> 534100 | Z43: =SUM(Z19:Z40) -> 698134 | AD43: =SUM(AD19:AD40) -> 884891 | AH43: =SUM(AH19:AH42) -> 830664 | AL43: =SUM(AL19:AL42) -> 542130 | AP43: =SUM(AP19:AP42) -> 650998 | AT43: =SUM(AT19:AT42) -> 731154 | AX43: =SUM(AX19:AX42) -> 852282 | BB43: =SUM(BB19:BB42) -> 572277 | BF43: =SUM(BF19:BF42) -> 778328 | BJ43: =SUM(BJ19:BJ42) -> 1464758 | BN43: =SUM(BN19:BN42) -> 785813 | BR43: =SUM(BR19:BR42) -> 705590 | BV43: =SUM(BV19:BV42) -> 819558 | BZ43: =SUM(BZ19:BZ42) -> 4114035 | CD43: =SUM(CD19:CD42) -> 783572 | CH43: =SUM(CH19:CH42) -> 813732 | CL43: =SUM(CL19:CL42) -> 1221338 | CP43: =SUM(CP19:CP42) -> 1194342 | CT43: =SUM(CT19:CT42) -> 583171 | CX43: =SUM(CX19:CX42) -> 9240359
B44: Cash in Hand - Closing Balance | H44: =H8+F16-F43 -> 5868083 | L44: =L8+J16-J43 -> 5402512 | P44: =P8+N16-N43 -> 4906871 | T44: =T8+R16-R43 -> 6708131.5 | X44: =X8+V16-V43 -> 6335031.5 | AB44: =AB8+Z16-Z43 -> 5916397.5 | AF44: =AF8+AD16-AD43 -> 7296569.5 | AJ44: =AJ8+AH16-AH43 -> 6644905.5 | AN44: =AN8+AL16-AL43 -> 6393275.5 | AR44: =AR8+AP16-AP43 -> 8088340.5 | AV44: =AV8+AT16-AT43 -> 7578686.5 | AZ44: =AZ8+AX16-AX43 -> 7140404.5 | BD44: =BD8+BB16-BB43 -> 8934190.5 | BH44: =BH8+BF16-BF43 -> 8376862.5 | BL44: =BL8+BJ16-BJ43 -> 7269104.5 | BP44: =BP8+BN16-BN43 -> 6903791.5 | BT44: =BT8+BR16-BR43 -> 8155264.1 | BX44: =BX8+BV16-BV43 -> 7555206.1 | CB44: =CB8+BZ16-BZ43 -> 3819671.1 | CF44: =CF8+CD16-CD43 -> 6119099.1 | CJ44: =CJ8+CH16-CH43 -> 6605867.1 | CN44: =CN8+CL16-CL43 -> 6121029.1 | CR44: =CR8+CP16-CP43 -> 6154187.1 | CV44: =CV8+CT16-CT43 -> 6442017.1
B46: Funds in Hand
